{
 "cells": [
  {
   "cell_type": "code",
   "execution_count": null,
   "id": "fluid-province",
   "metadata": {},
   "outputs": [
    {
     "name": "stderr",
     "output_type": "stream",
     "text": [
      "ERROR:root:Internal Python error in the inspect module.\n",
      "Below is the traceback from this internal error.\n",
      "\n",
      "ERROR:root:Internal Python error in the inspect module.\n",
      "Below is the traceback from this internal error.\n",
      "\n",
      "ERROR:root:Internal Python error in the inspect module.\n",
      "Below is the traceback from this internal error.\n",
      "\n"
     ]
    },
    {
     "name": "stdout",
     "output_type": "stream",
     "text": [
      "Traceback (most recent call last):\n",
      "  File \"/Users/samkatterfield/opt/miniconda3/lib/python3.8/site-packages/IPython/core/interactiveshell.py\", line 3437, in run_code\n",
      "    exec(code_obj, self.user_global_ns, self.user_ns)\n",
      "  File \"<ipython-input-1-e53162a10349>\", line 1, in <module>\n",
      "    import pandas as pd\n",
      "  File \"<frozen importlib._bootstrap>\", line 991, in _find_and_load\n",
      "  File \"<frozen importlib._bootstrap>\", line 971, in _find_and_load_unlocked\n",
      "  File \"<frozen importlib._bootstrap>\", line 914, in _find_spec\n",
      "  File \"<frozen importlib._bootstrap_external>\", line 1342, in find_spec\n",
      "  File \"<frozen importlib._bootstrap_external>\", line 1311, in _get_spec\n",
      "  File \"<frozen importlib._bootstrap_external>\", line 1275, in _path_importer_cache\n",
      "PermissionError: [Errno 1] Operation not permitted\n",
      "\n",
      "During handling of the above exception, another exception occurred:\n",
      "\n",
      "Traceback (most recent call last):\n",
      "  File \"/Users/samkatterfield/opt/miniconda3/lib/python3.8/site-packages/IPython/core/interactiveshell.py\", line 2061, in showtraceback\n",
      "    stb = value._render_traceback_()\n",
      "AttributeError: 'PermissionError' object has no attribute '_render_traceback_'\n",
      "\n",
      "During handling of the above exception, another exception occurred:\n",
      "\n",
      "Traceback (most recent call last):\n",
      "  File \"/Users/samkatterfield/opt/miniconda3/lib/python3.8/site-packages/IPython/core/ultratb.py\", line 1101, in get_records\n",
      "    return _fixed_getinnerframes(etb, number_of_lines_of_context, tb_offset)\n",
      "  File \"/Users/samkatterfield/opt/miniconda3/lib/python3.8/site-packages/IPython/core/ultratb.py\", line 248, in wrapped\n",
      "    return f(*args, **kwargs)\n",
      "  File \"/Users/samkatterfield/opt/miniconda3/lib/python3.8/site-packages/IPython/core/ultratb.py\", line 281, in _fixed_getinnerframes\n",
      "    records = fix_frame_records_filenames(inspect.getinnerframes(etb, context))\n",
      "  File \"/Users/samkatterfield/opt/miniconda3/lib/python3.8/inspect.py\", line 1503, in getinnerframes\n",
      "    frameinfo = (tb.tb_frame,) + getframeinfo(tb, context)\n",
      "  File \"/Users/samkatterfield/opt/miniconda3/lib/python3.8/inspect.py\", line 1461, in getframeinfo\n",
      "    filename = getsourcefile(frame) or getfile(frame)\n",
      "  File \"/Users/samkatterfield/opt/miniconda3/lib/python3.8/inspect.py\", line 708, in getsourcefile\n",
      "    if getattr(getmodule(object, filename), '__loader__', None) is not None:\n",
      "  File \"/Users/samkatterfield/opt/miniconda3/lib/python3.8/inspect.py\", line 737, in getmodule\n",
      "    file = getabsfile(object, _filename)\n",
      "  File \"/Users/samkatterfield/opt/miniconda3/lib/python3.8/inspect.py\", line 721, in getabsfile\n",
      "    return os.path.normcase(os.path.abspath(_filename))\n",
      "  File \"/Users/samkatterfield/opt/miniconda3/lib/python3.8/posixpath.py\", line 379, in abspath\n",
      "    cwd = os.getcwd()\n",
      "PermissionError: [Errno 1] Operation not permitted\n",
      "Traceback (most recent call last):\n",
      "  File \"/Users/samkatterfield/opt/miniconda3/lib/python3.8/site-packages/IPython/core/interactiveshell.py\", line 3437, in run_code\n",
      "    exec(code_obj, self.user_global_ns, self.user_ns)\n",
      "  File \"<ipython-input-1-e53162a10349>\", line 1, in <module>\n",
      "    import pandas as pd\n",
      "  File \"<frozen importlib._bootstrap>\", line 991, in _find_and_load\n",
      "  File \"<frozen importlib._bootstrap>\", line 971, in _find_and_load_unlocked\n",
      "  File \"<frozen importlib._bootstrap>\", line 914, in _find_spec\n",
      "  File \"<frozen importlib._bootstrap_external>\", line 1342, in find_spec\n",
      "  File \"<frozen importlib._bootstrap_external>\", line 1311, in _get_spec\n",
      "  File \"<frozen importlib._bootstrap_external>\", line 1275, in _path_importer_cache\n",
      "PermissionError: [Errno 1] Operation not permitted\n",
      "\n",
      "During handling of the above exception, another exception occurred:\n",
      "\n",
      "Traceback (most recent call last):\n",
      "  File \"/Users/samkatterfield/opt/miniconda3/lib/python3.8/site-packages/IPython/core/interactiveshell.py\", line 2061, in showtraceback\n",
      "    stb = value._render_traceback_()\n",
      "AttributeError: 'PermissionError' object has no attribute '_render_traceback_'\n",
      "\n",
      "During handling of the above exception, another exception occurred:\n",
      "\n",
      "Traceback (most recent call last):\n",
      "  File \"/Users/samkatterfield/opt/miniconda3/lib/python3.8/site-packages/IPython/core/interactiveshell.py\", line 3357, in run_ast_nodes\n",
      "    if (await self.run_code(code, result,  async_=asy)):\n",
      "  File \"/Users/samkatterfield/opt/miniconda3/lib/python3.8/site-packages/IPython/core/interactiveshell.py\", line 3454, in run_code\n",
      "    self.showtraceback(running_compiled_code=True)\n",
      "  File \"/Users/samkatterfield/opt/miniconda3/lib/python3.8/site-packages/IPython/core/interactiveshell.py\", line 2063, in showtraceback\n",
      "    stb = self.InteractiveTB.structured_traceback(etype,\n",
      "  File \"/Users/samkatterfield/opt/miniconda3/lib/python3.8/site-packages/IPython/core/ultratb.py\", line 1367, in structured_traceback\n",
      "    return FormattedTB.structured_traceback(\n",
      "  File \"/Users/samkatterfield/opt/miniconda3/lib/python3.8/site-packages/IPython/core/ultratb.py\", line 1267, in structured_traceback\n",
      "    return VerboseTB.structured_traceback(\n",
      "  File \"/Users/samkatterfield/opt/miniconda3/lib/python3.8/site-packages/IPython/core/ultratb.py\", line 1124, in structured_traceback\n",
      "    formatted_exception = self.format_exception_as_a_whole(etype, evalue, etb, number_of_lines_of_context,\n",
      "  File \"/Users/samkatterfield/opt/miniconda3/lib/python3.8/site-packages/IPython/core/ultratb.py\", line 1082, in format_exception_as_a_whole\n",
      "    last_unique, recursion_repeat = find_recursion(orig_etype, evalue, records)\n",
      "  File \"/Users/samkatterfield/opt/miniconda3/lib/python3.8/site-packages/IPython/core/ultratb.py\", line 382, in find_recursion\n",
      "    return len(records), 0\n",
      "TypeError: object of type 'NoneType' has no len()\n",
      "\n",
      "During handling of the above exception, another exception occurred:\n",
      "\n",
      "Traceback (most recent call last):\n",
      "  File \"/Users/samkatterfield/opt/miniconda3/lib/python3.8/site-packages/IPython/core/interactiveshell.py\", line 2061, in showtraceback\n",
      "    stb = value._render_traceback_()\n",
      "AttributeError: 'TypeError' object has no attribute '_render_traceback_'\n",
      "\n",
      "During handling of the above exception, another exception occurred:\n",
      "\n",
      "Traceback (most recent call last):\n",
      "  File \"/Users/samkatterfield/opt/miniconda3/lib/python3.8/site-packages/IPython/core/ultratb.py\", line 1101, in get_records\n",
      "    return _fixed_getinnerframes(etb, number_of_lines_of_context, tb_offset)\n",
      "  File \"/Users/samkatterfield/opt/miniconda3/lib/python3.8/site-packages/IPython/core/ultratb.py\", line 248, in wrapped\n",
      "    return f(*args, **kwargs)\n",
      "  File \"/Users/samkatterfield/opt/miniconda3/lib/python3.8/site-packages/IPython/core/ultratb.py\", line 281, in _fixed_getinnerframes\n",
      "    records = fix_frame_records_filenames(inspect.getinnerframes(etb, context))\n",
      "  File \"/Users/samkatterfield/opt/miniconda3/lib/python3.8/inspect.py\", line 1503, in getinnerframes\n",
      "    frameinfo = (tb.tb_frame,) + getframeinfo(tb, context)\n",
      "  File \"/Users/samkatterfield/opt/miniconda3/lib/python3.8/inspect.py\", line 1461, in getframeinfo\n",
      "    filename = getsourcefile(frame) or getfile(frame)\n",
      "  File \"/Users/samkatterfield/opt/miniconda3/lib/python3.8/inspect.py\", line 708, in getsourcefile\n",
      "    if getattr(getmodule(object, filename), '__loader__', None) is not None:\n",
      "  File \"/Users/samkatterfield/opt/miniconda3/lib/python3.8/inspect.py\", line 737, in getmodule\n",
      "    file = getabsfile(object, _filename)\n",
      "  File \"/Users/samkatterfield/opt/miniconda3/lib/python3.8/inspect.py\", line 721, in getabsfile\n",
      "    return os.path.normcase(os.path.abspath(_filename))\n",
      "  File \"/Users/samkatterfield/opt/miniconda3/lib/python3.8/posixpath.py\", line 379, in abspath\n",
      "    cwd = os.getcwd()\n",
      "PermissionError: [Errno 1] Operation not permitted\n",
      "Traceback (most recent call last):\n",
      "  File \"/Users/samkatterfield/opt/miniconda3/lib/python3.8/site-packages/IPython/core/interactiveshell.py\", line 3437, in run_code\n",
      "    exec(code_obj, self.user_global_ns, self.user_ns)\n",
      "  File \"<ipython-input-1-e53162a10349>\", line 1, in <module>\n",
      "    import pandas as pd\n",
      "  File \"<frozen importlib._bootstrap>\", line 991, in _find_and_load\n",
      "  File \"<frozen importlib._bootstrap>\", line 971, in _find_and_load_unlocked\n",
      "  File \"<frozen importlib._bootstrap>\", line 914, in _find_spec\n",
      "  File \"<frozen importlib._bootstrap_external>\", line 1342, in find_spec\n",
      "  File \"<frozen importlib._bootstrap_external>\", line 1311, in _get_spec\n",
      "  File \"<frozen importlib._bootstrap_external>\", line 1275, in _path_importer_cache\n",
      "PermissionError: [Errno 1] Operation not permitted\n",
      "\n",
      "During handling of the above exception, another exception occurred:\n",
      "\n",
      "Traceback (most recent call last):\n",
      "  File \"/Users/samkatterfield/opt/miniconda3/lib/python3.8/site-packages/IPython/core/interactiveshell.py\", line 2061, in showtraceback\n",
      "    stb = value._render_traceback_()\n",
      "AttributeError: 'PermissionError' object has no attribute '_render_traceback_'\n",
      "\n",
      "During handling of the above exception, another exception occurred:\n",
      "\n",
      "Traceback (most recent call last):\n",
      "  File \"/Users/samkatterfield/opt/miniconda3/lib/python3.8/site-packages/IPython/core/interactiveshell.py\", line 3357, in run_ast_nodes\n",
      "    if (await self.run_code(code, result,  async_=asy)):\n",
      "  File \"/Users/samkatterfield/opt/miniconda3/lib/python3.8/site-packages/IPython/core/interactiveshell.py\", line 3454, in run_code\n",
      "    self.showtraceback(running_compiled_code=True)\n",
      "  File \"/Users/samkatterfield/opt/miniconda3/lib/python3.8/site-packages/IPython/core/interactiveshell.py\", line 2063, in showtraceback\n",
      "    stb = self.InteractiveTB.structured_traceback(etype,\n",
      "  File \"/Users/samkatterfield/opt/miniconda3/lib/python3.8/site-packages/IPython/core/ultratb.py\", line 1367, in structured_traceback\n",
      "    return FormattedTB.structured_traceback(\n",
      "  File \"/Users/samkatterfield/opt/miniconda3/lib/python3.8/site-packages/IPython/core/ultratb.py\", line 1267, in structured_traceback\n",
      "    return VerboseTB.structured_traceback(\n",
      "  File \"/Users/samkatterfield/opt/miniconda3/lib/python3.8/site-packages/IPython/core/ultratb.py\", line 1124, in structured_traceback\n",
      "    formatted_exception = self.format_exception_as_a_whole(etype, evalue, etb, number_of_lines_of_context,\n",
      "  File \"/Users/samkatterfield/opt/miniconda3/lib/python3.8/site-packages/IPython/core/ultratb.py\", line 1082, in format_exception_as_a_whole\n",
      "    last_unique, recursion_repeat = find_recursion(orig_etype, evalue, records)\n",
      "  File \"/Users/samkatterfield/opt/miniconda3/lib/python3.8/site-packages/IPython/core/ultratb.py\", line 382, in find_recursion\n",
      "    return len(records), 0\n",
      "TypeError: object of type 'NoneType' has no len()\n",
      "\n",
      "During handling of the above exception, another exception occurred:\n",
      "\n",
      "Traceback (most recent call last):\n",
      "  File \"/Users/samkatterfield/opt/miniconda3/lib/python3.8/site-packages/IPython/core/interactiveshell.py\", line 2061, in showtraceback\n",
      "    stb = value._render_traceback_()\n",
      "AttributeError: 'TypeError' object has no attribute '_render_traceback_'\n",
      "\n",
      "During handling of the above exception, another exception occurred:\n",
      "\n",
      "Traceback (most recent call last):\n",
      "  File \"/Users/samkatterfield/opt/miniconda3/lib/python3.8/site-packages/IPython/core/interactiveshell.py\", line 2940, in _run_cell\n",
      "    return runner(coro)\n",
      "  File \"/Users/samkatterfield/opt/miniconda3/lib/python3.8/site-packages/IPython/core/async_helpers.py\", line 68, in _pseudo_sync_runner\n",
      "    coro.send(None)\n",
      "  File \"/Users/samkatterfield/opt/miniconda3/lib/python3.8/site-packages/IPython/core/interactiveshell.py\", line 3165, in run_cell_async\n",
      "    has_raised = await self.run_ast_nodes(code_ast.body, cell_name,\n",
      "  File \"/Users/samkatterfield/opt/miniconda3/lib/python3.8/site-packages/IPython/core/interactiveshell.py\", line 3376, in run_ast_nodes\n",
      "    self.showtraceback()\n",
      "  File \"/Users/samkatterfield/opt/miniconda3/lib/python3.8/site-packages/IPython/core/interactiveshell.py\", line 2063, in showtraceback\n",
      "    stb = self.InteractiveTB.structured_traceback(etype,\n",
      "  File \"/Users/samkatterfield/opt/miniconda3/lib/python3.8/site-packages/IPython/core/ultratb.py\", line 1367, in structured_traceback\n",
      "    return FormattedTB.structured_traceback(\n",
      "  File \"/Users/samkatterfield/opt/miniconda3/lib/python3.8/site-packages/IPython/core/ultratb.py\", line 1267, in structured_traceback\n",
      "    return VerboseTB.structured_traceback(\n",
      "  File \"/Users/samkatterfield/opt/miniconda3/lib/python3.8/site-packages/IPython/core/ultratb.py\", line 1142, in structured_traceback\n",
      "    formatted_exceptions += self.format_exception_as_a_whole(etype, evalue, etb, lines_of_context,\n",
      "  File \"/Users/samkatterfield/opt/miniconda3/lib/python3.8/site-packages/IPython/core/ultratb.py\", line 1082, in format_exception_as_a_whole\n",
      "    last_unique, recursion_repeat = find_recursion(orig_etype, evalue, records)\n",
      "  File \"/Users/samkatterfield/opt/miniconda3/lib/python3.8/site-packages/IPython/core/ultratb.py\", line 382, in find_recursion\n",
      "    return len(records), 0\n",
      "TypeError: object of type 'NoneType' has no len()\n",
      "\n",
      "During handling of the above exception, another exception occurred:\n",
      "\n",
      "Traceback (most recent call last):\n",
      "  File \"/Users/samkatterfield/opt/miniconda3/lib/python3.8/site-packages/IPython/core/interactiveshell.py\", line 2061, in showtraceback\n",
      "    stb = value._render_traceback_()\n",
      "AttributeError: 'TypeError' object has no attribute '_render_traceback_'\n",
      "\n",
      "During handling of the above exception, another exception occurred:\n",
      "\n",
      "Traceback (most recent call last):\n",
      "  File \"/Users/samkatterfield/opt/miniconda3/lib/python3.8/site-packages/IPython/core/ultratb.py\", line 1101, in get_records\n",
      "    return _fixed_getinnerframes(etb, number_of_lines_of_context, tb_offset)\n",
      "  File \"/Users/samkatterfield/opt/miniconda3/lib/python3.8/site-packages/IPython/core/ultratb.py\", line 248, in wrapped\n",
      "    return f(*args, **kwargs)\n",
      "  File \"/Users/samkatterfield/opt/miniconda3/lib/python3.8/site-packages/IPython/core/ultratb.py\", line 281, in _fixed_getinnerframes\n",
      "    records = fix_frame_records_filenames(inspect.getinnerframes(etb, context))\n",
      "  File \"/Users/samkatterfield/opt/miniconda3/lib/python3.8/inspect.py\", line 1503, in getinnerframes\n",
      "    frameinfo = (tb.tb_frame,) + getframeinfo(tb, context)\n",
      "  File \"/Users/samkatterfield/opt/miniconda3/lib/python3.8/inspect.py\", line 1461, in getframeinfo\n",
      "    filename = getsourcefile(frame) or getfile(frame)\n",
      "  File \"/Users/samkatterfield/opt/miniconda3/lib/python3.8/inspect.py\", line 708, in getsourcefile\n",
      "    if getattr(getmodule(object, filename), '__loader__', None) is not None:\n",
      "  File \"/Users/samkatterfield/opt/miniconda3/lib/python3.8/inspect.py\", line 737, in getmodule\n",
      "    file = getabsfile(object, _filename)\n",
      "  File \"/Users/samkatterfield/opt/miniconda3/lib/python3.8/inspect.py\", line 721, in getabsfile\n",
      "    return os.path.normcase(os.path.abspath(_filename))\n",
      "  File \"/Users/samkatterfield/opt/miniconda3/lib/python3.8/posixpath.py\", line 379, in abspath\n",
      "    cwd = os.getcwd()\n",
      "PermissionError: [Errno 1] Operation not permitted\n"
     ]
    }
   ],
   "source": [
    "import pandas as pd\n",
    "\n",
    "df = pd.read_csv('food_recipes.csv')"
   ]
  }
 ],
 "metadata": {
  "kernelspec": {
   "display_name": "Python 3",
   "language": "python",
   "name": "python3"
  },
  "language_info": {
   "codemirror_mode": {
    "name": "ipython",
    "version": 3
   },
   "file_extension": ".py",
   "mimetype": "text/x-python",
   "name": "python",
   "nbconvert_exporter": "python",
   "pygments_lexer": "ipython3",
   "version": "3.8.5"
  }
 },
 "nbformat": 4,
 "nbformat_minor": 5
}
